[2024-12-03T15:49:28.938+0000] {local_task_job_runner.py:123} INFO - ::group::Pre task execution logs
[2024-12-03T15:49:28.966+0000] {taskinstance.py:2613} INFO - Dependencies all met for dep_context=non-requeueable deps ti=<TaskInstance: finance_data_generator.generate_and_store_data manual__2024-12-03T15:49:19.918489+00:00 [queued]>
[2024-12-03T15:49:28.979+0000] {taskinstance.py:2613} INFO - Dependencies all met for dep_context=requeueable deps ti=<TaskInstance: finance_data_generator.generate_and_store_data manual__2024-12-03T15:49:19.918489+00:00 [queued]>
[2024-12-03T15:49:28.980+0000] {taskinstance.py:2866} INFO - Starting attempt 1 of 2
[2024-12-03T15:49:29.004+0000] {taskinstance.py:2889} INFO - Executing <Task(PythonOperator): generate_and_store_data> on 2024-12-03 15:49:19.918489+00:00
[2024-12-03T15:49:29.013+0000] {warnings.py:112} WARNING - /home/airflow/.local/lib/python3.12/site-packages/airflow/task/task_runner/standard_task_runner.py:70: DeprecationWarning: This process (pid=82) is multi-threaded, use of fork() may lead to deadlocks in the child.
  pid = os.fork()

[2024-12-03T15:49:29.015+0000] {standard_task_runner.py:72} INFO - Started process 85 to run task
[2024-12-03T15:49:29.019+0000] {standard_task_runner.py:104} INFO - Running: ['airflow', 'tasks', 'run', 'finance_data_generator', 'generate_and_store_data', 'manual__2024-12-03T15:49:19.918489+00:00', '--job-id', '3', '--raw', '--subdir', 'DAGS_FOLDER/finance_data_generator.py', '--cfg-path', '/tmp/tmp0n4sehz1']
[2024-12-03T15:49:29.021+0000] {standard_task_runner.py:105} INFO - Job 3: Subtask generate_and_store_data
[2024-12-03T15:49:29.111+0000] {task_command.py:467} INFO - Running <TaskInstance: finance_data_generator.generate_and_store_data manual__2024-12-03T15:49:19.918489+00:00 [running]> on host bd8ab49cf491
[2024-12-03T15:49:29.261+0000] {taskinstance.py:3132} INFO - Exporting env vars: AIRFLOW_CTX_DAG_OWNER='airflow' AIRFLOW_CTX_DAG_ID='finance_data_generator' AIRFLOW_CTX_TASK_ID='generate_and_store_data' AIRFLOW_CTX_EXECUTION_DATE='2024-12-03T15:49:19.918489+00:00' AIRFLOW_CTX_TRY_NUMBER='1' AIRFLOW_CTX_DAG_RUN_ID='manual__2024-12-03T15:49:19.918489+00:00'
[2024-12-03T15:49:29.263+0000] {logging_mixin.py:190} INFO - Task instance is in running state
[2024-12-03T15:49:29.263+0000] {logging_mixin.py:190} INFO -  Previous state of the Task instance: queued
[2024-12-03T15:49:29.264+0000] {logging_mixin.py:190} INFO - Current task name:generate_and_store_data state:running start_date:2024-12-03 15:49:28.967089+00:00
[2024-12-03T15:49:29.264+0000] {logging_mixin.py:190} INFO - Dag name:finance_data_generator and current dag run status:running
[2024-12-03T15:49:29.265+0000] {taskinstance.py:731} INFO - ::endgroup::
[2024-12-03T15:50:04.444+0000] {local_task_job_runner.py:346} WARNING - State of this instance has been externally set to restarting. Terminating instance.
[2024-12-03T15:50:04.445+0000] {local_task_job_runner.py:245} INFO - ::endgroup::
[2024-12-03T15:50:04.449+0000] {process_utils.py:132} INFO - Sending 15 to group 85. PIDs of all processes in the group: [85]
[2024-12-03T15:50:04.450+0000] {process_utils.py:87} INFO - Sending the signal 15 to group 85
[2024-12-03T15:50:49.723+0000] {taskinstance.py:3093} ERROR - Received SIGTERM. Terminating subprocesses.
[2024-12-03T15:50:49.725+0000] {logging_mixin.py:190} INFO - Error storing transactions: Can't reconnect until invalid transaction is rolled back. (Background on this error at: https://sqlalche.me/e/14/8s2b)
[2024-12-03T15:50:49.731+0000] {taskinstance.py:3311} ERROR - Task failed with exception
Traceback (most recent call last):
  File "/opt/airflow/dags/finance_data_generator.py", line 23, in generate_and_store_data
    store_transactions_to_db(df, engine)
  File "/opt/airflow/dags/utils/db_operations.py", line 28, in store_transactions_to_db
    df.to_sql('transactions', engine, if_exists='replace', index=False)
  File "/home/airflow/.local/lib/python3.12/site-packages/pandas/util/_decorators.py", line 333, in wrapper
    return func(*args, **kwargs)
           ^^^^^^^^^^^^^^^^^^^^^
  File "/home/airflow/.local/lib/python3.12/site-packages/pandas/core/generic.py", line 3008, in to_sql
    return sql.to_sql(
           ^^^^^^^^^^^
  File "/home/airflow/.local/lib/python3.12/site-packages/pandas/io/sql.py", line 787, in to_sql
    with pandasSQL_builder(con, schema=schema, need_transaction=True) as pandas_sql:
         ^^^^^^^^^^^^^^^^^^^^^^^^^^^^^^^^^^^^^^^^^^^^^^^^^^^^^^^^^^^^
  File "/home/airflow/.local/lib/python3.12/site-packages/pandas/io/sql.py", line 1585, in __exit__
    self.exit_stack.close()
  File "/usr/local/lib/python3.12/contextlib.py", line 618, in close
    self.__exit__(None, None, None)
  File "/usr/local/lib/python3.12/contextlib.py", line 610, in __exit__
    raise exc_details[1]
  File "/usr/local/lib/python3.12/contextlib.py", line 595, in __exit__
    if cb(*exc_details):
       ^^^^^^^^^^^^^^^^
  File "/home/airflow/.local/lib/python3.12/site-packages/sqlalchemy/engine/util.py", line 235, in __exit__
    with util.safe_reraise():
         ^^^^^^^^^^^^^^^^^^^
  File "/home/airflow/.local/lib/python3.12/site-packages/sqlalchemy/util/langhelpers.py", line 70, in __exit__
    compat.raise_(
  File "/home/airflow/.local/lib/python3.12/site-packages/sqlalchemy/util/compat.py", line 211, in raise_
    raise exception
  File "/home/airflow/.local/lib/python3.12/site-packages/sqlalchemy/engine/util.py", line 233, in __exit__
    self.commit()
  File "/home/airflow/.local/lib/python3.12/site-packages/sqlalchemy/engine/base.py", line 2469, in commit
    self._do_commit()
  File "/home/airflow/.local/lib/python3.12/site-packages/sqlalchemy/engine/base.py", line 2659, in _do_commit
    self._connection_commit_impl()
  File "/home/airflow/.local/lib/python3.12/site-packages/sqlalchemy/engine/base.py", line 2630, in _connection_commit_impl
    self.connection._commit_impl()
  File "/home/airflow/.local/lib/python3.12/site-packages/sqlalchemy/engine/base.py", line 1096, in _commit_impl
    self._handle_dbapi_exception(e, None, None, None, None)
  File "/home/airflow/.local/lib/python3.12/site-packages/sqlalchemy/engine/base.py", line 2138, in _handle_dbapi_exception
    util.raise_(exc_info[1], with_traceback=exc_info[2])
  File "/home/airflow/.local/lib/python3.12/site-packages/sqlalchemy/util/compat.py", line 211, in raise_
    raise exception
  File "/home/airflow/.local/lib/python3.12/site-packages/sqlalchemy/engine/base.py", line 1094, in _commit_impl
    self.engine.dialect.do_commit(self.connection)
                                  ^^^^^^^^^^^^^^^
  File "/home/airflow/.local/lib/python3.12/site-packages/sqlalchemy/engine/base.py", line 537, in connection
    return self._revalidate_connection()
           ^^^^^^^^^^^^^^^^^^^^^^^^^^^^^
  File "/home/airflow/.local/lib/python3.12/site-packages/sqlalchemy/engine/base.py", line 650, in _revalidate_connection
    self._invalid_transaction()
  File "/home/airflow/.local/lib/python3.12/site-packages/sqlalchemy/engine/base.py", line 622, in _invalid_transaction
    raise exc.PendingRollbackError(
sqlalchemy.exc.PendingRollbackError: Can't reconnect until invalid transaction is rolled back. (Background on this error at: https://sqlalche.me/e/14/8s2b)

During handling of the above exception, another exception occurred:

Traceback (most recent call last):
  File "/home/airflow/.local/lib/python3.12/site-packages/airflow/models/taskinstance.py", line 767, in _execute_task
    result = _execute_callable(context=context, **execute_callable_kwargs)
             ^^^^^^^^^^^^^^^^^^^^^^^^^^^^^^^^^^^^^^^^^^^^^^^^^^^^^^^^^^^^^
  File "/home/airflow/.local/lib/python3.12/site-packages/airflow/models/taskinstance.py", line 733, in _execute_callable
    return ExecutionCallableRunner(
           ^^^^^^^^^^^^^^^^^^^^^^^^
  File "/home/airflow/.local/lib/python3.12/site-packages/airflow/utils/operator_helpers.py", line 252, in run
    return self.func(*args, **kwargs)
           ^^^^^^^^^^^^^^^^^^^^^^^^^^
  File "/home/airflow/.local/lib/python3.12/site-packages/airflow/models/baseoperator.py", line 417, in wrapper
    return func(self, *args, **kwargs)
           ^^^^^^^^^^^^^^^^^^^^^^^^^^^
  File "/home/airflow/.local/lib/python3.12/site-packages/airflow/operators/python.py", line 238, in execute
    return_value = self.execute_callable()
                   ^^^^^^^^^^^^^^^^^^^^^^^
  File "/home/airflow/.local/lib/python3.12/site-packages/airflow/operators/python.py", line 256, in execute_callable
    return runner.run(*self.op_args, **self.op_kwargs)
           ^^^^^^^^^^^^^^^^^^^^^^^^^^^^^^^^^^^^^^^^^^^
  File "/home/airflow/.local/lib/python3.12/site-packages/airflow/utils/operator_helpers.py", line 252, in run
    return self.func(*args, **kwargs)
           ^^^^^^^^^^^^^^^^^^^^^^^^^^
  File "/opt/airflow/dags/finance_data_generator.py", line 25, in generate_and_store_data
    raise AirflowFailException(f"Data generation or storage failed: {e}")
airflow.exceptions.AirflowFailException: Data generation or storage failed: Can't reconnect until invalid transaction is rolled back. (Background on this error at: https://sqlalche.me/e/14/8s2b)
[2024-12-03T15:50:49.798+0000] {logging_mixin.py:190} INFO - Task instance in failure state
[2024-12-03T15:50:49.800+0000] {logging_mixin.py:190} INFO - Task start:2024-12-03 15:49:28.967089+00:00 end:2024-12-03 15:50:49.797682+00:00 duration:80.830593
[2024-12-03T15:50:49.801+0000] {logging_mixin.py:190} INFO - Task:<Task(PythonOperator): generate_and_store_data> dag:<DAG: finance_data_generator> dagrun:<DagRun finance_data_generator @ 2024-12-03 15:49:19.918489+00:00: manual__2024-12-03T15:49:19.918489+00:00, state:running, queued_at: 2024-12-03 15:49:19.962670+00:00. externally triggered: True>
[2024-12-03T15:50:49.801+0000] {logging_mixin.py:190} INFO - Failure caused by Data generation or storage failed: Can't reconnect until invalid transaction is rolled back. (Background on this error at: https://sqlalche.me/e/14/8s2b)
[2024-12-03T15:50:49.803+0000] {taskinstance.py:1225} INFO - Immediate failure requested. Marking task as FAILED. dag_id=finance_data_generator, task_id=generate_and_store_data, run_id=manual__2024-12-03T15:49:19.918489+00:00, execution_date=20241203T154919, start_date=20241203T154928, end_date=20241203T155049
[2024-12-03T15:50:49.867+0000] {taskinstance.py:340} INFO - ::group::Post task execution logs
[2024-12-03T15:50:49.869+0000] {standard_task_runner.py:124} ERROR - Failed to execute job 3 for task generate_and_store_data (Data generation or storage failed: Can't reconnect until invalid transaction is rolled back. (Background on this error at: https://sqlalche.me/e/14/8s2b); 85)
Traceback (most recent call last):
  File "/opt/airflow/dags/finance_data_generator.py", line 23, in generate_and_store_data
    store_transactions_to_db(df, engine)
  File "/opt/airflow/dags/utils/db_operations.py", line 28, in store_transactions_to_db
    df.to_sql('transactions', engine, if_exists='replace', index=False)
  File "/home/airflow/.local/lib/python3.12/site-packages/pandas/util/_decorators.py", line 333, in wrapper
    return func(*args, **kwargs)
           ^^^^^^^^^^^^^^^^^^^^^
  File "/home/airflow/.local/lib/python3.12/site-packages/pandas/core/generic.py", line 3008, in to_sql
    return sql.to_sql(
           ^^^^^^^^^^^
  File "/home/airflow/.local/lib/python3.12/site-packages/pandas/io/sql.py", line 787, in to_sql
    with pandasSQL_builder(con, schema=schema, need_transaction=True) as pandas_sql:
         ^^^^^^^^^^^^^^^^^^^^^^^^^^^^^^^^^^^^^^^^^^^^^^^^^^^^^^^^^^^^
  File "/home/airflow/.local/lib/python3.12/site-packages/pandas/io/sql.py", line 1585, in __exit__
    self.exit_stack.close()
  File "/usr/local/lib/python3.12/contextlib.py", line 618, in close
    self.__exit__(None, None, None)
  File "/usr/local/lib/python3.12/contextlib.py", line 610, in __exit__
    raise exc_details[1]
  File "/usr/local/lib/python3.12/contextlib.py", line 595, in __exit__
    if cb(*exc_details):
       ^^^^^^^^^^^^^^^^
  File "/home/airflow/.local/lib/python3.12/site-packages/sqlalchemy/engine/util.py", line 235, in __exit__
    with util.safe_reraise():
         ^^^^^^^^^^^^^^^^^^^
  File "/home/airflow/.local/lib/python3.12/site-packages/sqlalchemy/util/langhelpers.py", line 70, in __exit__
    compat.raise_(
  File "/home/airflow/.local/lib/python3.12/site-packages/sqlalchemy/util/compat.py", line 211, in raise_
    raise exception
  File "/home/airflow/.local/lib/python3.12/site-packages/sqlalchemy/engine/util.py", line 233, in __exit__
    self.commit()
  File "/home/airflow/.local/lib/python3.12/site-packages/sqlalchemy/engine/base.py", line 2469, in commit
    self._do_commit()
  File "/home/airflow/.local/lib/python3.12/site-packages/sqlalchemy/engine/base.py", line 2659, in _do_commit
    self._connection_commit_impl()
  File "/home/airflow/.local/lib/python3.12/site-packages/sqlalchemy/engine/base.py", line 2630, in _connection_commit_impl
    self.connection._commit_impl()
  File "/home/airflow/.local/lib/python3.12/site-packages/sqlalchemy/engine/base.py", line 1096, in _commit_impl
    self._handle_dbapi_exception(e, None, None, None, None)
  File "/home/airflow/.local/lib/python3.12/site-packages/sqlalchemy/engine/base.py", line 2138, in _handle_dbapi_exception
    util.raise_(exc_info[1], with_traceback=exc_info[2])
  File "/home/airflow/.local/lib/python3.12/site-packages/sqlalchemy/util/compat.py", line 211, in raise_
    raise exception
  File "/home/airflow/.local/lib/python3.12/site-packages/sqlalchemy/engine/base.py", line 1094, in _commit_impl
    self.engine.dialect.do_commit(self.connection)
                                  ^^^^^^^^^^^^^^^
  File "/home/airflow/.local/lib/python3.12/site-packages/sqlalchemy/engine/base.py", line 537, in connection
    return self._revalidate_connection()
           ^^^^^^^^^^^^^^^^^^^^^^^^^^^^^
  File "/home/airflow/.local/lib/python3.12/site-packages/sqlalchemy/engine/base.py", line 650, in _revalidate_connection
    self._invalid_transaction()
  File "/home/airflow/.local/lib/python3.12/site-packages/sqlalchemy/engine/base.py", line 622, in _invalid_transaction
    raise exc.PendingRollbackError(
sqlalchemy.exc.PendingRollbackError: Can't reconnect until invalid transaction is rolled back. (Background on this error at: https://sqlalche.me/e/14/8s2b)

During handling of the above exception, another exception occurred:

Traceback (most recent call last):
  File "/home/airflow/.local/lib/python3.12/site-packages/airflow/task/task_runner/standard_task_runner.py", line 117, in _start_by_fork
    ret = args.func(args, dag=self.dag)
          ^^^^^^^^^^^^^^^^^^^^^^^^^^^^^
  File "/home/airflow/.local/lib/python3.12/site-packages/airflow/cli/cli_config.py", line 49, in command
    return func(*args, **kwargs)
           ^^^^^^^^^^^^^^^^^^^^^
  File "/home/airflow/.local/lib/python3.12/site-packages/airflow/utils/cli.py", line 116, in wrapper
    return f(*args, **kwargs)
           ^^^^^^^^^^^^^^^^^^
  File "/home/airflow/.local/lib/python3.12/site-packages/airflow/cli/commands/task_command.py", line 483, in task_run
    task_return_code = _run_task_by_selected_method(args, _dag, ti)
                       ^^^^^^^^^^^^^^^^^^^^^^^^^^^^^^^^^^^^^^^^^^^^
  File "/home/airflow/.local/lib/python3.12/site-packages/airflow/cli/commands/task_command.py", line 256, in _run_task_by_selected_method
    return _run_raw_task(args, ti)
           ^^^^^^^^^^^^^^^^^^^^^^^
  File "/home/airflow/.local/lib/python3.12/site-packages/airflow/cli/commands/task_command.py", line 341, in _run_raw_task
    return ti._run_raw_task(
           ^^^^^^^^^^^^^^^^^
  File "/home/airflow/.local/lib/python3.12/site-packages/airflow/utils/session.py", line 97, in wrapper
    return func(*args, session=session, **kwargs)
           ^^^^^^^^^^^^^^^^^^^^^^^^^^^^^^^^^^^^^^
  File "/home/airflow/.local/lib/python3.12/site-packages/airflow/models/taskinstance.py", line 3005, in _run_raw_task
    return _run_raw_task(
           ^^^^^^^^^^^^^^
  File "/home/airflow/.local/lib/python3.12/site-packages/airflow/models/taskinstance.py", line 273, in _run_raw_task
    TaskInstance._execute_task_with_callbacks(
  File "/home/airflow/.local/lib/python3.12/site-packages/airflow/models/taskinstance.py", line 3159, in _execute_task_with_callbacks
    result = self._execute_task(context, task_orig)
             ^^^^^^^^^^^^^^^^^^^^^^^^^^^^^^^^^^^^^^
  File "/home/airflow/.local/lib/python3.12/site-packages/airflow/models/taskinstance.py", line 3183, in _execute_task
    return _execute_task(self, context, task_orig)
           ^^^^^^^^^^^^^^^^^^^^^^^^^^^^^^^^^^^^^^^
  File "/home/airflow/.local/lib/python3.12/site-packages/airflow/models/taskinstance.py", line 767, in _execute_task
    result = _execute_callable(context=context, **execute_callable_kwargs)
             ^^^^^^^^^^^^^^^^^^^^^^^^^^^^^^^^^^^^^^^^^^^^^^^^^^^^^^^^^^^^^
  File "/home/airflow/.local/lib/python3.12/site-packages/airflow/models/taskinstance.py", line 733, in _execute_callable
    return ExecutionCallableRunner(
           ^^^^^^^^^^^^^^^^^^^^^^^^
  File "/home/airflow/.local/lib/python3.12/site-packages/airflow/utils/operator_helpers.py", line 252, in run
    return self.func(*args, **kwargs)
           ^^^^^^^^^^^^^^^^^^^^^^^^^^
  File "/home/airflow/.local/lib/python3.12/site-packages/airflow/models/baseoperator.py", line 417, in wrapper
    return func(self, *args, **kwargs)
           ^^^^^^^^^^^^^^^^^^^^^^^^^^^
  File "/home/airflow/.local/lib/python3.12/site-packages/airflow/operators/python.py", line 238, in execute
    return_value = self.execute_callable()
                   ^^^^^^^^^^^^^^^^^^^^^^^
  File "/home/airflow/.local/lib/python3.12/site-packages/airflow/operators/python.py", line 256, in execute_callable
    return runner.run(*self.op_args, **self.op_kwargs)
           ^^^^^^^^^^^^^^^^^^^^^^^^^^^^^^^^^^^^^^^^^^^
  File "/home/airflow/.local/lib/python3.12/site-packages/airflow/utils/operator_helpers.py", line 252, in run
    return self.func(*args, **kwargs)
           ^^^^^^^^^^^^^^^^^^^^^^^^^^
  File "/opt/airflow/dags/finance_data_generator.py", line 25, in generate_and_store_data
    raise AirflowFailException(f"Data generation or storage failed: {e}")
airflow.exceptions.AirflowFailException: Data generation or storage failed: Can't reconnect until invalid transaction is rolled back. (Background on this error at: https://sqlalche.me/e/14/8s2b)
[2024-12-03T15:50:49.947+0000] {process_utils.py:80} INFO - Process psutil.Process(pid=85, status='terminated', exitcode=1, started='15:49:28') (85) terminated with exit code 1
