[2024-12-05T06:14:17.911+0000] {local_task_job_runner.py:123} INFO - ::group::Pre task execution logs
[2024-12-05T06:14:17.935+0000] {taskinstance.py:2613} INFO - Dependencies all met for dep_context=non-requeueable deps ti=<TaskInstance: finance_data_generator.generate_and_store_data scheduled__2024-12-05T06:12:00+00:00 [queued]>
[2024-12-05T06:14:17.945+0000] {taskinstance.py:2613} INFO - Dependencies all met for dep_context=requeueable deps ti=<TaskInstance: finance_data_generator.generate_and_store_data scheduled__2024-12-05T06:12:00+00:00 [queued]>
[2024-12-05T06:14:17.946+0000] {taskinstance.py:2866} INFO - Starting attempt 1 of 2
[2024-12-05T06:14:17.968+0000] {taskinstance.py:2889} INFO - Executing <Task(PythonOperator): generate_and_store_data> on 2024-12-05 06:12:00+00:00
[2024-12-05T06:14:17.977+0000] {warnings.py:112} WARNING - /home/airflow/.local/lib/python3.12/site-packages/airflow/task/task_runner/standard_task_runner.py:70: DeprecationWarning: This process (pid=75) is multi-threaded, use of fork() may lead to deadlocks in the child.
  pid = os.fork()

[2024-12-05T06:14:17.979+0000] {standard_task_runner.py:72} INFO - Started process 82 to run task
[2024-12-05T06:14:17.980+0000] {standard_task_runner.py:104} INFO - Running: ['airflow', 'tasks', 'run', 'finance_data_generator', 'generate_and_store_data', 'scheduled__2024-12-05T06:12:00+00:00', '--job-id', '4', '--raw', '--subdir', 'DAGS_FOLDER/finance_data_generator.py', '--cfg-path', '/tmp/tmpicph6y14']
[2024-12-05T06:14:17.981+0000] {standard_task_runner.py:105} INFO - Job 4: Subtask generate_and_store_data
[2024-12-05T06:14:18.054+0000] {task_command.py:467} INFO - Running <TaskInstance: finance_data_generator.generate_and_store_data scheduled__2024-12-05T06:12:00+00:00 [running]> on host 35934f8fe887
[2024-12-05T06:14:18.163+0000] {taskinstance.py:3132} INFO - Exporting env vars: AIRFLOW_CTX_DAG_OWNER='airflow' AIRFLOW_CTX_DAG_ID='finance_data_generator' AIRFLOW_CTX_TASK_ID='generate_and_store_data' AIRFLOW_CTX_EXECUTION_DATE='2024-12-05T06:12:00+00:00' AIRFLOW_CTX_TRY_NUMBER='1' AIRFLOW_CTX_DAG_RUN_ID='scheduled__2024-12-05T06:12:00+00:00'
[2024-12-05T06:14:18.165+0000] {logging_mixin.py:190} INFO - Task instance is in running state
[2024-12-05T06:14:18.165+0000] {logging_mixin.py:190} INFO -  Previous state of the Task instance: queued
[2024-12-05T06:14:18.165+0000] {logging_mixin.py:190} INFO - Current task name:generate_and_store_data state:running start_date:2024-12-05 06:14:17.935608+00:00
[2024-12-05T06:14:18.165+0000] {logging_mixin.py:190} INFO - Dag name:finance_data_generator and current dag run status:running
[2024-12-05T06:14:18.166+0000] {taskinstance.py:731} INFO - ::endgroup::
[2024-12-05T06:14:18.182+0000] {taskinstance.py:3311} ERROR - Task failed with exception
Traceback (most recent call last):
  File "/home/airflow/.local/lib/python3.12/site-packages/cryptography/fernet.py", line 34, in __init__
    key = base64.urlsafe_b64decode(key)
          ^^^^^^^^^^^^^^^^^^^^^^^^^^^^^
  File "/usr/local/lib/python3.12/base64.py", line 134, in urlsafe_b64decode
    return b64decode(s)
           ^^^^^^^^^^^^
  File "/usr/local/lib/python3.12/base64.py", line 88, in b64decode
    return binascii.a2b_base64(s, strict_mode=validate)
           ^^^^^^^^^^^^^^^^^^^^^^^^^^^^^^^^^^^^^^^^^^^^
binascii.Error: Incorrect padding

The above exception was the direct cause of the following exception:

Traceback (most recent call last):
  File "/home/airflow/.local/lib/python3.12/site-packages/airflow/models/crypto.py", line 86, in get_fernet
    [Fernet(fernet_part.encode("utf-8")) for fernet_part in fernet_key.split(",")]
     ^^^^^^^^^^^^^^^^^^^^^^^^^^^^^^^^^^^
  File "/home/airflow/.local/lib/python3.12/site-packages/cryptography/fernet.py", line 36, in __init__
    raise ValueError(
ValueError: Fernet key must be 32 url-safe base64-encoded bytes.

During handling of the above exception, another exception occurred:

Traceback (most recent call last):
  File "/opt/airflow/dags/finance_data_generator.py", line 22, in generate_and_store_data
    df = generate_financial_transactions()
         ^^^^^^^^^^^^^^^^^^^^^^^^^^^^^^^^^
  File "/opt/airflow/dags/utils/data_generator.py", line 54, in generate_financial_transactions
    'transaction_id': generate_transaction_ids(size),
                      ^^^^^^^^^^^^^^^^^^^^^^^^^^^^^^
  File "/opt/airflow/dags/utils/data_generator.py", line 13, in generate_transaction_ids
    Variable.set('last_transaction_id', list(ids)[-1])
  File "/home/airflow/.local/lib/python3.12/site-packages/airflow/utils/session.py", line 97, in wrapper
    return func(*args, session=session, **kwargs)
           ^^^^^^^^^^^^^^^^^^^^^^^^^^^^^^^^^^^^^^
  File "/home/airflow/.local/lib/python3.12/site-packages/airflow/models/variable.py", line 175, in set
    Variable._set(
  File "/home/airflow/.local/lib/python3.12/site-packages/airflow/utils/session.py", line 94, in wrapper
    return func(*args, **kwargs)
           ^^^^^^^^^^^^^^^^^^^^^
  File "/home/airflow/.local/lib/python3.12/site-packages/airflow/api_internal/internal_api_call.py", line 166, in wrapper
    return func(*args, **kwargs)
           ^^^^^^^^^^^^^^^^^^^^^
  File "/home/airflow/.local/lib/python3.12/site-packages/airflow/models/variable.py", line 212, in _set
    session.add(Variable(key=key, val=stored_value, description=description))
                ^^^^^^^^^^^^^^^^^^^^^^^^^^^^^^^^^^^^^^^^^^^^^^^^^^^^^^^^^^^^
  File "<string>", line 4, in __init__
  File "/home/airflow/.local/lib/python3.12/site-packages/sqlalchemy/orm/state.py", line 481, in _initialize_instance
    with util.safe_reraise():
         ^^^^^^^^^^^^^^^^^^^
  File "/home/airflow/.local/lib/python3.12/site-packages/sqlalchemy/util/langhelpers.py", line 70, in __exit__
    compat.raise_(
  File "/home/airflow/.local/lib/python3.12/site-packages/sqlalchemy/util/compat.py", line 211, in raise_
    raise exception
  File "/home/airflow/.local/lib/python3.12/site-packages/sqlalchemy/orm/state.py", line 479, in _initialize_instance
    return manager.original_init(*mixed[1:], **kwargs)
           ^^^^^^^^^^^^^^^^^^^^^^^^^^^^^^^^^^^^^^^^^^^
  File "/home/airflow/.local/lib/python3.12/site-packages/airflow/models/variable.py", line 59, in __init__
    self.val = val
    ^^^^^^^^
  File "<string>", line 1, in __set__
  File "/home/airflow/.local/lib/python3.12/site-packages/airflow/models/variable.py", line 91, in set_val
    fernet = get_fernet()
             ^^^^^^^^^^^^
  File "/home/airflow/.local/lib/python3.12/site-packages/airflow/models/crypto.py", line 90, in get_fernet
    raise AirflowException(f"Could not create Fernet object: {value_error}")
airflow.exceptions.AirflowException: Could not create Fernet object: Fernet key must be 32 url-safe base64-encoded bytes.

During handling of the above exception, another exception occurred:

Traceback (most recent call last):
  File "/home/airflow/.local/lib/python3.12/site-packages/airflow/models/taskinstance.py", line 767, in _execute_task
    result = _execute_callable(context=context, **execute_callable_kwargs)
             ^^^^^^^^^^^^^^^^^^^^^^^^^^^^^^^^^^^^^^^^^^^^^^^^^^^^^^^^^^^^^
  File "/home/airflow/.local/lib/python3.12/site-packages/airflow/models/taskinstance.py", line 733, in _execute_callable
    return ExecutionCallableRunner(
           ^^^^^^^^^^^^^^^^^^^^^^^^
  File "/home/airflow/.local/lib/python3.12/site-packages/airflow/utils/operator_helpers.py", line 252, in run
    return self.func(*args, **kwargs)
           ^^^^^^^^^^^^^^^^^^^^^^^^^^
  File "/home/airflow/.local/lib/python3.12/site-packages/airflow/models/baseoperator.py", line 417, in wrapper
    return func(self, *args, **kwargs)
           ^^^^^^^^^^^^^^^^^^^^^^^^^^^
  File "/home/airflow/.local/lib/python3.12/site-packages/airflow/operators/python.py", line 238, in execute
    return_value = self.execute_callable()
                   ^^^^^^^^^^^^^^^^^^^^^^^
  File "/home/airflow/.local/lib/python3.12/site-packages/airflow/operators/python.py", line 256, in execute_callable
    return runner.run(*self.op_args, **self.op_kwargs)
           ^^^^^^^^^^^^^^^^^^^^^^^^^^^^^^^^^^^^^^^^^^^
  File "/home/airflow/.local/lib/python3.12/site-packages/airflow/utils/operator_helpers.py", line 252, in run
    return self.func(*args, **kwargs)
           ^^^^^^^^^^^^^^^^^^^^^^^^^^
  File "/opt/airflow/dags/finance_data_generator.py", line 26, in generate_and_store_data
    raise AirflowFailException(f"Data generation or storage failed: {e}")
airflow.exceptions.AirflowFailException: Data generation or storage failed: Could not create Fernet object: Fernet key must be 32 url-safe base64-encoded bytes.
[2024-12-05T06:14:18.201+0000] {logging_mixin.py:190} INFO - Task instance in failure state
[2024-12-05T06:14:18.202+0000] {logging_mixin.py:190} INFO - Task start:2024-12-05 06:14:17.935608+00:00 end:2024-12-05 06:14:18.201193+00:00 duration:0.265585
[2024-12-05T06:14:18.202+0000] {logging_mixin.py:190} INFO - Task:<Task(PythonOperator): generate_and_store_data> dag:<DAG: finance_data_generator> dagrun:<DagRun finance_data_generator @ 2024-12-05 06:12:00+00:00: scheduled__2024-12-05T06:12:00+00:00, state:running, queued_at: 2024-12-05 06:14:12.924360+00:00. externally triggered: False>
[2024-12-05T06:14:18.202+0000] {logging_mixin.py:190} INFO - Failure caused by Data generation or storage failed: Could not create Fernet object: Fernet key must be 32 url-safe base64-encoded bytes.
[2024-12-05T06:14:18.203+0000] {taskinstance.py:1225} INFO - Immediate failure requested. Marking task as FAILED. dag_id=finance_data_generator, task_id=generate_and_store_data, run_id=scheduled__2024-12-05T06:12:00+00:00, execution_date=20241205T061200, start_date=20241205T061417, end_date=20241205T061418
[2024-12-05T06:14:18.218+0000] {taskinstance.py:340} INFO - ::group::Post task execution logs
[2024-12-05T06:14:18.219+0000] {standard_task_runner.py:124} ERROR - Failed to execute job 4 for task generate_and_store_data (Data generation or storage failed: Could not create Fernet object: Fernet key must be 32 url-safe base64-encoded bytes.; 82)
Traceback (most recent call last):
  File "/home/airflow/.local/lib/python3.12/site-packages/cryptography/fernet.py", line 34, in __init__
    key = base64.urlsafe_b64decode(key)
          ^^^^^^^^^^^^^^^^^^^^^^^^^^^^^
  File "/usr/local/lib/python3.12/base64.py", line 134, in urlsafe_b64decode
    return b64decode(s)
           ^^^^^^^^^^^^
  File "/usr/local/lib/python3.12/base64.py", line 88, in b64decode
    return binascii.a2b_base64(s, strict_mode=validate)
           ^^^^^^^^^^^^^^^^^^^^^^^^^^^^^^^^^^^^^^^^^^^^
binascii.Error: Incorrect padding

The above exception was the direct cause of the following exception:

Traceback (most recent call last):
  File "/home/airflow/.local/lib/python3.12/site-packages/airflow/models/crypto.py", line 86, in get_fernet
    [Fernet(fernet_part.encode("utf-8")) for fernet_part in fernet_key.split(",")]
     ^^^^^^^^^^^^^^^^^^^^^^^^^^^^^^^^^^^
  File "/home/airflow/.local/lib/python3.12/site-packages/cryptography/fernet.py", line 36, in __init__
    raise ValueError(
ValueError: Fernet key must be 32 url-safe base64-encoded bytes.

During handling of the above exception, another exception occurred:

Traceback (most recent call last):
  File "/opt/airflow/dags/finance_data_generator.py", line 22, in generate_and_store_data
    df = generate_financial_transactions()
         ^^^^^^^^^^^^^^^^^^^^^^^^^^^^^^^^^
  File "/opt/airflow/dags/utils/data_generator.py", line 54, in generate_financial_transactions
    'transaction_id': generate_transaction_ids(size),
                      ^^^^^^^^^^^^^^^^^^^^^^^^^^^^^^
  File "/opt/airflow/dags/utils/data_generator.py", line 13, in generate_transaction_ids
    Variable.set('last_transaction_id', list(ids)[-1])
  File "/home/airflow/.local/lib/python3.12/site-packages/airflow/utils/session.py", line 97, in wrapper
    return func(*args, session=session, **kwargs)
           ^^^^^^^^^^^^^^^^^^^^^^^^^^^^^^^^^^^^^^
  File "/home/airflow/.local/lib/python3.12/site-packages/airflow/models/variable.py", line 175, in set
    Variable._set(
  File "/home/airflow/.local/lib/python3.12/site-packages/airflow/utils/session.py", line 94, in wrapper
    return func(*args, **kwargs)
           ^^^^^^^^^^^^^^^^^^^^^
  File "/home/airflow/.local/lib/python3.12/site-packages/airflow/api_internal/internal_api_call.py", line 166, in wrapper
    return func(*args, **kwargs)
           ^^^^^^^^^^^^^^^^^^^^^
  File "/home/airflow/.local/lib/python3.12/site-packages/airflow/models/variable.py", line 212, in _set
    session.add(Variable(key=key, val=stored_value, description=description))
                ^^^^^^^^^^^^^^^^^^^^^^^^^^^^^^^^^^^^^^^^^^^^^^^^^^^^^^^^^^^^
  File "<string>", line 4, in __init__
  File "/home/airflow/.local/lib/python3.12/site-packages/sqlalchemy/orm/state.py", line 481, in _initialize_instance
    with util.safe_reraise():
         ^^^^^^^^^^^^^^^^^^^
  File "/home/airflow/.local/lib/python3.12/site-packages/sqlalchemy/util/langhelpers.py", line 70, in __exit__
    compat.raise_(
  File "/home/airflow/.local/lib/python3.12/site-packages/sqlalchemy/util/compat.py", line 211, in raise_
    raise exception
  File "/home/airflow/.local/lib/python3.12/site-packages/sqlalchemy/orm/state.py", line 479, in _initialize_instance
    return manager.original_init(*mixed[1:], **kwargs)
           ^^^^^^^^^^^^^^^^^^^^^^^^^^^^^^^^^^^^^^^^^^^
  File "/home/airflow/.local/lib/python3.12/site-packages/airflow/models/variable.py", line 59, in __init__
    self.val = val
    ^^^^^^^^
  File "<string>", line 1, in __set__
  File "/home/airflow/.local/lib/python3.12/site-packages/airflow/models/variable.py", line 91, in set_val
    fernet = get_fernet()
             ^^^^^^^^^^^^
  File "/home/airflow/.local/lib/python3.12/site-packages/airflow/models/crypto.py", line 90, in get_fernet
    raise AirflowException(f"Could not create Fernet object: {value_error}")
airflow.exceptions.AirflowException: Could not create Fernet object: Fernet key must be 32 url-safe base64-encoded bytes.

During handling of the above exception, another exception occurred:

Traceback (most recent call last):
  File "/home/airflow/.local/lib/python3.12/site-packages/airflow/task/task_runner/standard_task_runner.py", line 117, in _start_by_fork
    ret = args.func(args, dag=self.dag)
          ^^^^^^^^^^^^^^^^^^^^^^^^^^^^^
  File "/home/airflow/.local/lib/python3.12/site-packages/airflow/cli/cli_config.py", line 49, in command
    return func(*args, **kwargs)
           ^^^^^^^^^^^^^^^^^^^^^
  File "/home/airflow/.local/lib/python3.12/site-packages/airflow/utils/cli.py", line 116, in wrapper
    return f(*args, **kwargs)
           ^^^^^^^^^^^^^^^^^^
  File "/home/airflow/.local/lib/python3.12/site-packages/airflow/cli/commands/task_command.py", line 483, in task_run
    task_return_code = _run_task_by_selected_method(args, _dag, ti)
                       ^^^^^^^^^^^^^^^^^^^^^^^^^^^^^^^^^^^^^^^^^^^^
  File "/home/airflow/.local/lib/python3.12/site-packages/airflow/cli/commands/task_command.py", line 256, in _run_task_by_selected_method
    return _run_raw_task(args, ti)
           ^^^^^^^^^^^^^^^^^^^^^^^
  File "/home/airflow/.local/lib/python3.12/site-packages/airflow/cli/commands/task_command.py", line 341, in _run_raw_task
    return ti._run_raw_task(
           ^^^^^^^^^^^^^^^^^
  File "/home/airflow/.local/lib/python3.12/site-packages/airflow/utils/session.py", line 97, in wrapper
    return func(*args, session=session, **kwargs)
           ^^^^^^^^^^^^^^^^^^^^^^^^^^^^^^^^^^^^^^
  File "/home/airflow/.local/lib/python3.12/site-packages/airflow/models/taskinstance.py", line 3005, in _run_raw_task
    return _run_raw_task(
           ^^^^^^^^^^^^^^
  File "/home/airflow/.local/lib/python3.12/site-packages/airflow/models/taskinstance.py", line 273, in _run_raw_task
    TaskInstance._execute_task_with_callbacks(
  File "/home/airflow/.local/lib/python3.12/site-packages/airflow/models/taskinstance.py", line 3159, in _execute_task_with_callbacks
    result = self._execute_task(context, task_orig)
             ^^^^^^^^^^^^^^^^^^^^^^^^^^^^^^^^^^^^^^
  File "/home/airflow/.local/lib/python3.12/site-packages/airflow/models/taskinstance.py", line 3183, in _execute_task
    return _execute_task(self, context, task_orig)
           ^^^^^^^^^^^^^^^^^^^^^^^^^^^^^^^^^^^^^^^
  File "/home/airflow/.local/lib/python3.12/site-packages/airflow/models/taskinstance.py", line 767, in _execute_task
    result = _execute_callable(context=context, **execute_callable_kwargs)
             ^^^^^^^^^^^^^^^^^^^^^^^^^^^^^^^^^^^^^^^^^^^^^^^^^^^^^^^^^^^^^
  File "/home/airflow/.local/lib/python3.12/site-packages/airflow/models/taskinstance.py", line 733, in _execute_callable
    return ExecutionCallableRunner(
           ^^^^^^^^^^^^^^^^^^^^^^^^
  File "/home/airflow/.local/lib/python3.12/site-packages/airflow/utils/operator_helpers.py", line 252, in run
    return self.func(*args, **kwargs)
           ^^^^^^^^^^^^^^^^^^^^^^^^^^
  File "/home/airflow/.local/lib/python3.12/site-packages/airflow/models/baseoperator.py", line 417, in wrapper
    return func(self, *args, **kwargs)
           ^^^^^^^^^^^^^^^^^^^^^^^^^^^
  File "/home/airflow/.local/lib/python3.12/site-packages/airflow/operators/python.py", line 238, in execute
    return_value = self.execute_callable()
                   ^^^^^^^^^^^^^^^^^^^^^^^
  File "/home/airflow/.local/lib/python3.12/site-packages/airflow/operators/python.py", line 256, in execute_callable
    return runner.run(*self.op_args, **self.op_kwargs)
           ^^^^^^^^^^^^^^^^^^^^^^^^^^^^^^^^^^^^^^^^^^^
  File "/home/airflow/.local/lib/python3.12/site-packages/airflow/utils/operator_helpers.py", line 252, in run
    return self.func(*args, **kwargs)
           ^^^^^^^^^^^^^^^^^^^^^^^^^^
  File "/opt/airflow/dags/finance_data_generator.py", line 26, in generate_and_store_data
    raise AirflowFailException(f"Data generation or storage failed: {e}")
airflow.exceptions.AirflowFailException: Data generation or storage failed: Could not create Fernet object: Fernet key must be 32 url-safe base64-encoded bytes.
[2024-12-05T06:14:18.275+0000] {local_task_job_runner.py:266} INFO - Task exited with return code 1
[2024-12-05T06:14:18.302+0000] {taskinstance.py:3895} INFO - 0 downstream tasks scheduled from follow-on schedule check
[2024-12-05T06:14:18.304+0000] {local_task_job_runner.py:245} INFO - ::endgroup::
